Workbook

Sheet Notice
B2: Référentiel des investissements CAPEX — plan Sedima 2030
B3: Source unique de vérité pour les projets d'investissement CAPEX 2026-2030. Quatre niveaux : portefeuille, tâches, répartition pluriannuelle, contrôles de bouclage. Le fichier data.js sera généré depuis ce classeur — aucune saisie directe dans data.js.
B5: RÈGLES RETENUES
B6: Deux colonnes de montant | C6: Enveloppe approuvée / Coût reconstruit | E6: L'enveloppe est le budget validé ; le coût reconstruit est la somme des tâches ou des offres reçues. L'écart entre les deux est l'information de pilotage.
B7: Périmètre | C7: CAPEX uniquement | E7: Sont exclus gouvernance, recrutements, budget marketing et primes des fermes intégrées. Le Pilier I ne porte aucun CAPEX.
B8: Enveloppes KPMG | C8: HTVA | E8: Budgets du plan, buffer de 15 % inclus, traités hors taxes.
B9: Droits de douane | C9: 5 % de la part importée | E9: Portés par les seules tâches de commande d'équipements importés.
B10: TVA | C10: 18 % × (HTVA + douanes) | E10: Règle unique appliquée au coût reconstruit.
B11: Priorité de la donnée | C11: Contrat > Offres > Devis > Plan KPMG > Estimation | E11: Un montant contractuel ou devisé remplace l'enveloppe du plan, même si le portefeuille dépasse les 37,7 Mds.
B12: Codification | C12: Séquentielle PI-nn | E12: Un code n'est jamais réutilisé sans purge préalable de son antériorité.
B13: Complémentarité | C13: Explicite | E13: Deux offres complémentaires s'additionnent, deux offres concurrentes jamais. Les doublons sont déduits et journalisés.
B15: STATUTS DE CYCLE DE VIE
B16: Plan | C16: Inscrit au plan stratégique | E16: Ni cadré ni consulté.
B17: Cadrage | C17: Périmètre en cours de définition | E17: Découpage en lots établi, consultation lancée ou offres reçues.
B18: Approuvé | C18: Enveloppe validée par le Comité | E18: Prêt à engager.
B19: Engagé | C19: Contrat signé ou bon de commande émis | E19: Décaissements commencés ou imminents.
B20: En exécution | C20: Travaux ou fabrication en cours | E20: Suivi de la valeur acquise actif.
B21: Clôturé | C21: Réception prononcée, réserves levées | E21: Le code n'est pas réutilisable.
B22: Hors périmètre | C22: Retiré temporairement du pilotage | E22: Remises à niveau de bâtiments d'élevage.
B24: QUALITÉ DE LA DONNÉE
B25: Contrat | C25: Engagement signé ou bon de commande | E25: Fait foi.
B26: Offres | C26: Devis fournisseurs reçus | E26: Fait foi.
B27: Plan KPMG | C27: Chiffrage préliminaire du plan | E27: Ordre de grandeur, buffer de 15 % inclus.
B28: Estimation | C28: Ratio ou avis d'expert | E28: Aucune source externe.
B30: ONGLET TÂCHES
B31: Couverture | C31: 19 projets sur 28 · 583 tâches | E31: 68 % du portefeuille en valeur. Neuf projets restent sans découpage : PI-11, PI-12, PI-15, PI-16, PI-21, PI-22, PI-23, PI-27 et PI-28.
B32: Origine | C32: Trois sources | E32: PI-03 à PI-06 du fichier de saisie validé ; PI-01, PI-02, PI-07 à PI-10 des découpages établis avec Claude ; PI-13, PI-14, PI-17 à PI-20, PI-24 à PI-26 générés depuis un gabarit.
B33: Contrôle | C33: Somme des tâches = coût reconstruit | E33: Vérifié par formule dans l'onglet Contrôle.

Sheet Portefeuille
B2: Portefeuille des investissements CAPEX 2026-2030
B3: 28 projets, dont 25 pilotés et 3 hors périmètre. Deux colonnes de montant : l'enveloppe approuvée et le coût reconstruit sur les tâches ou les offres. L'écart entre les deux est la donnée de pilotage. Lignes vertes : contrat ou offres reçues. Lignes jaunes : chiffrage KPMG ou estimation. Lignes rosées : hors périmètre. Douanes, TVA et TTC sont calculés sur le coût reconstruit.
B5: Code | C5: Pilier | D5: Bucket | E5: Objectif du plan | F5: PP | G5: BU | H5: Nom du projet | I5: Site | J5: Chef de projet | K5: Nature (modèle WBS) | L5: Statut | M5: Début | N5: Fin | O5: Année | P5: Enveloppe approuvée | Q5: Coût reconstruit | R5: Écart | S5: Douanes | T5: TVA | U5: Total TTC | V5: Enveloppe KPMG | W5: Qualité | X5: Tâches | Y5: Source | Z5: Commentaire
B6: PI-02 | C6: III | D6: Œufs de table | E6: Accroître et saturer les capacités de production | F6: 11 | G6: PPAP | H6: Nouveau bâtiment PAP17 | I6: TBD | J6: Assane Gueye | K6: Ferme / bâtiment d'élevage | L6: Cadrage | M6: 2026-01 | N6: 2027-04 | O6: 2026 | P6: 1000000000 | Q6: 1000000000 | R6: =Q6-P6 -> 0 | S6: 50000000 | T6: =ROUND((Q6+S6)*0.18,0) -> 189000000 | U6: =Q6+S6+T6 -> 1239000000 | V6: 1000000000 | W6: Plan KPMG | X6: 32 | Y6: KPMG p. 75 — 3 000 M pour 3 fermes type Karaouni 2 | Z6: 180 000 places sur 4 bâtiments. Site non arrêté. Découpage en 10 lots établi.
B7: PI-03 | C7: III | D7: OAC & Poussins | E7: Accroître et saturer les capacités de production | F7: 11 | G7: OAC | H7: Extension ferme OAC | I7: Notto | J7: Assane Gueye | K7: Ferme / bâtiment d'élevage | L7: Cadrage | M7: 2026-01 | N7: 2027-06 | O7: 2026 | P7: 2929000000 | Q7: 2899710000 | R7: =Q7-P7 -> -29290000 | S7: 70300471 | T7: =ROUND((Q7+S7)*0.18,0) -> 534601885 | U7: =Q7+S7+T7 -> 3504612356 | V7: 2800000000 | W7: Offres | X7: 30 | Y7: Scénario A — NTD DEV25-161 et DEV25-160 (structure, CIF Dakar), VDL Agrotech OPP-2502 et OPP-2509, VDL Jansen 3024834, Roxell 3044EQ1041264 (équipement) | Z7: 6 offres couvrent 1 406 009 418 F, soit 48 % : 4 repro chair, 2 poussinières, 1 bâtiment coqs. Reliquat 1 522 990 582 F pour génie civil, VRD, électricité, montage et douane, tous exclus des offres — à chiffrer. Douanes ramenées à 5 % de la part importée ; l'ancienne base de 85 100 000 était inexpliquée et produisait la TVA incohérente.
B8: PI-06 | C8: III | D8: OAC & Poussins | E8: Automatiser les processus industriels | F8: 13 | G8: Couvoir | H8: Automatisation Couvoir | I8: Notto | J8: Yacine Diop | K8: Usine et process industriel | L8: Engagé | M8: 2026-01 | N8: 2026-12 | O8: 2026 | P8: 171310464 | Q8: 207934725 | R8: =Q8-P8 -> 36624261 | S8: 8796736 | T8: =ROUND((Q8+S8)*0.18,0) -> 39011663 | U8: =Q8+S8+T8 -> 255743124 | V8: 160000000 | W8: Contrat | X8: 31 | Y8: NECTRA 132-A397c1 du 11/12/2025 signé + addendum n°1 + proforma 25P-00730-3 (200 000 € CIF Dakar) ; CIDAPE 25-1152 incubateur Petersime 576 (66 994,05 € CFR Dakar) et 26-1015 mission superviseur | Z8: Contrat signé côté NECTRA le 30/12/2025 — case SEDIMA vide au document, à vérifier. Remise NECTRA de 67 729 € sur 236 700 € d'équipements. Génie civil, découpes de cloisons et raccordement électrique exclus, non chiffrés. CIDAPE met à la charge du client hébergement, repas, déplacements du superviseur et une équipe locale de 3 agents, 1 électricien et 1 plombier.
B9: PI-07 | C9: III | D9: Poulets de chair | E9: Automatiser les processus industriels | F9: 13 | G9: Abattoir | H9: Remise à niveau abattoir | I9: Ndiar | J9: Thierry Gomis | K9: Usine et process industriel | L9: Engagé | M9: 2026-01 | N9: 2027-01 | O9: 2026 | P9: 700358080 | Q9: 1153434670 | R9: =Q9-P9 -> 453076590 | S9: 31081798 | T9: =ROUND((Q9+S9)*0.18,0) -> 213212964 | U9: =Q9+S9+T9 -> 1397729432 | V9: 160000000 | W9: Offres | X9: 56 | Y9: 12 offres — Frigo Indus 240805 (bon de commande BC18971) et 250109, Dakar Dur, Lassarat, AND steel, Afric Froid West, RENOSEN, CTB, Vendée Concept, Bobet, XUCLÀ, SONEDES, MULTIVAC | Z9: Chambre négative engagée par BC18971 du 24/09/2025 (130 000 €). Trois lots ajoutés après cadrage : emballage MULTIVAC solution 02, lavage de bacs XUCLÀ 500 c/h, hygiène SONEDES — 310 M à eux seuls. Écartés : GTI (94 188 709) au profit d'AND steel, RevoxY (32 599 000) au profit de Lassarat. Déduction Dakar Dur Zone 1 annulée : surfaces distinctes de l'emprise AND steel. MULTIVAC est un budget approximatif, pas un devis.
B10: PI-08 | C10: III | D10: Industriel | E10: Accroître et saturer les capacités de production | F10: 11 | G10: UA | H10: Extension UAB | I10: Usine | J10: Yacine Diop | K10: Usine et process industriel | L10: Engagé | M10: 2026-06 | N10: 2027-11 | O10: 2026 | P10: 3205744000 | Q10: 1832414627 | R10: =Q10-P10 -> -1373329373 | S10: 88115600 | T10: =ROUND((Q10+S10)*0.18,0) -> 345695441 | U10: =Q10+S10+T10 -> 2266225668 | V10: 2300000000 | W10: Contrat | X10: 29 | Y10: Contrat Bühler du 22/05/2026 — lots AN-26, AN-25 et WR-26, 2 264 500 € CFR Dakar | Z10: Exception au retrait des remises à niveau : contrat signé. GH-26 (680 600 €) reste non rattaché.
B11: PI-10 | C11: II | D11: Autres | E11: Refonte de la politique commerciale | F11: 10 | G11: IT | H11: Digitalisation 2026 | I11: Siège | J11: Ousmane Diongue | K11: Informatique | L11: Cadrage | M11: 2026-01 | N11: 2026-12 | O11: 2026 | P11: 105000000 | Q11: 126000000 | R11: =Q11-P11 -> 21000000 | S11: 0 | T11: =ROUND((Q11+S11)*0.18,0) -> 22680000 | U11: =Q11+S11+T11 -> 148680000 | V11: 115000000 | W11: Plan KPMG | X11: 11 | Y11: KPMG p. 10 — CRM 100 M (PP10) et plateforme e-commerce 15 M (PP8) | Z11: Seul projet Pilier II du portefeuille. Abonnement Salesforce en Opex, non chiffré.
B12: PI-11 | C12: III | D12: Œufs de table | E12: Automatiser les processus industriels | F12: 13 | G12: ODT | H12: Automatisation des pondoirs (12 bâtiments) | I12: Karaouni | J12: À définir | K12: Ferme / bâtiment d'élevage | L12: Plan | M12: 2026-01 | N12: 2026-12 | O12: 2026 | P12: 516000000 | Q12: 516000000 | R12: =Q12-P12 -> 0 | S12: 25800000 | T12: =ROUND((Q12+S12)*0.18,0) -> 97524000 | U12: =Q12+S12+T12 -> 639324000 | V12: 516000000 | W12: Plan KPMG | X12: — | Y12: KPMG p. 68 — 65 k€ par bâtiment sur 12 bâtiments, devis déjà obtenus | Z12: Travaux en bâtiments occupés : phasage sur les vides sanitaires obligatoire.
B13: PI-12 | C13: III | D13: Poulets de chair | E13: Étudier les opportunités de diversification | F13: 15 | G13: Abattoir | H13: Ligne de production de nuggets | I13: Ndiar | J13: À définir | K13: Usine et process industriel | L13: Cadrage | M13: 2026-01 | N13: 2026-07 | O13: 2026 | P13: 65000000 | Q13: 120939743 | R13: =Q13-P13 -> 55939743 | S13: 3246987 | T13: =ROUND((Q13+S13)*0.18,0) -> 22353611 | U13: =Q13+S13+T13 -> 146540341 | V13: 65000000 | W13: Offres | X13: 22 | Y13: MULTIVAC « Ligne de production de chicken nuggets » du 06/11/2025 — hachoir Kolbe SW114-II 1 300 kg/h, mélangeur A-100L 200 kg/h, poussoir Handtmann VF608 + formage, enrobeuse-panneuse 15 cycles/min, machine sous vide P400 : 99 000 € | Z13: 500 kg/jour de blanc de poulet, produit fini surgelé en sachets de 500 g à 1 kg, process maintenu entre -2 et 0 °C. Les 99 000 € couvrent les seules machines : ni surgélation, ni transport, ni installation, ni utilités. La surgélation est absente de l'offre alors que le conditionnement se fait à -20 °C — capacité du tunnel existant de l'abattoir à vérifier, sinon compter environ 35 M de plus. Le formage des nuggets est manuel : c'est le goulot de la ligne. Recette non définie.
B14: PI-04 | C14: III | D14: OAC & Poussins | E14: Accroître et saturer les capacités de production | F14: 11 | G14: OAC | H14: Ferme de production OAC ponte | I14: TBD | J14: Assane Gueye | K14: Ferme / bâtiment d'élevage | L14: Plan | M14: 2027-01 | N14: 2028-04 | O14: 2027 | P14: 1500000000 | Q14: 1500000000 | R14: =Q14-P14 -> 0 | S14: 75000000 | T14: =ROUND((Q14+S14)*0.18,0) -> 283500000 | U14: =Q14+S14+T14 -> 1858500000 | V14: 1500000000 | W14: Plan KPMG | X14: 35 | Y14: KPMG p. 75 — 4 500 M pour 3 nouvelles fermes ponte type Karaouni 1 | Z14: Intitulée « OAC ponte » dans le référentiel actuel : rattachement d'activité à corriger.
B15: PI-05 | C15: III | D15: Poulets de chair | E15: Accroître et saturer les capacités de production | F15: 11 | G15: OAC | H15: Ferme élevage poulet de chair | I15: TBD | J15: Assane Gueye | K15: Ferme / bâtiment d'élevage | L15: Plan | M15: 2027-01 | N15: 2028-04 | O15: 2027 | P15: 1246000000 | Q15: 1246000000 | R15: =Q15-P15 -> 0 | S15: 62300000 | T15: =ROUND((Q15+S15)*0.18,0) -> 235494000 | U15: =Q15+S15+T15 -> 1543794000 | V15: 1000000000 | W15: Estimation | X15: 30 | Y15: KPMG p. 75 — 3 000 M pour 3 fermes chair, buffer 15 % inclus | Z15: 360 000 poulets mis en place par ferme, 1 500 t pour l'abattoir.
B16: PI-09 | C16: III | D16: Autres | E16: Mettre à niveau la flotte logistique | F16: 14 | G16: Logistique | H16: Extension Flotte logistique | I16: Siège | J16: Matar Seck | K16: Logistique / flotte | L16: Plan | M16: 2027-01 | N16: 2028-06 | O16: 2027 | P16: 801500000 | Q16: 513000000 | R16: =Q16-P16 -> -288500000 | S16: 17750000 | T16: =ROUND((Q16+S16)*0.18,0) -> 95535000 | U16: =Q16+S16+T16 -> 626285000 | V16: 463000000 | W16: Plan KPMG | X16: 22 | Y16: KPMG p. 78 — achats de camions, démarrage 2027, livraison début 2028 | Z16: Traitement douanier et fiscal des véhicules à trancher par la DAF.
B17: PI-13 | C17: III | D17: OAC & Poussins | E17: Accroître et saturer les capacités de production | F17: 11 | G17: OAC | H17: Extension ferme OAC n°2 | I17: Notto | J17: À définir | K17: Ferme / bâtiment d'élevage | L17: Plan | M17: 2027-01 | N17: 2027-12 | O17: 2027 | P17: 2800000000 | Q17: 2800000000 | R17: =Q17-P17 -> 0 | S17: 140000000 | T17: =ROUND((Q17+S17)*0.18,0) -> 529200000 | U17: =Q17+S17+T17 -> 3469200000 | V17: 2800000000 | W17: Plan KPMG | X17: 30 | Y17: KPMG p. 17 — 4 extensions, une par an, sur poussinières et repro chair
B18: PI-14 | C18: III | D18: Œufs de table | E18: Accroître et saturer les capacités de production | F18: 11 | G18: PPAP | H18: Ferme poulettes 17 semaines n°2 | I18: TBD | J18: À définir | K18: Ferme / bâtiment d'élevage | L18: Plan | M18: 2027-01 | N18: 2028-04 | O18: 2027 | P18: 1000000000 | Q18: 1000000000 | R18: =Q18-P18 -> 0 | S18: 50000000 | T18: =ROUND((Q18+S18)*0.18,0) -> 189000000 | U18: =Q18+S18+T18 -> 1239000000 | V18: 1000000000 | W18: Plan KPMG | X18: 32 | Y18: KPMG p. 75 — deuxième des trois fermes type Karaouni 2 | Z18: Gabarit repris de PI-02 : 180 000 places, 4 bâtiments.
B19: PI-15 | C19: III | D19: Industriel | E19: Accroître et saturer les capacités de production | F19: 11 | G19: Farine | H19: Nouveau moulin | I19: TBD | J19: À définir | K19: Usine et process industriel | L19: Plan | M19: 2027-01 | N19: 2028-12 | O19: 2027 | P19: 6169000000 | Q19: 6169000000 | R19: =Q19-P19 -> 0 | S19: 308450000 | T19: =ROUND((Q19+S19)*0.18,0) -> 1165941000 | U19: =Q19+S19+T19 -> 7643391000 | V19: 6169000000 | W19: Plan KPMG | X19: — | Y19: KPMG p. 76 — 5 500 M moulin, 40 M Matador, 629 M stockage et logistique partagés | Z19: Plus gros projet du plan hors pâtes. Initialement prévu en 2025, repoussé à 2027.
B20: PI-16 | C20: III | D20: Poulets de chair | E20: Mettre à niveau la flotte logistique | F20: 14 | G20: Abattoir | H20: Optimisation des flux et du stockage (FIFO) | I20: Ndiar | J20: À définir | K20: Usine et process industriel | L20: Plan | M20: 2027-01 | N20: 2027-12 | O20: 2027 | P20: 300000000 | Q20: 300000000 | R20: =Q20-P20 -> 0 | S20: 15000000 | T20: =ROUND((Q20+S20)*0.18,0) -> 56700000 | U20: =Q20+S20+T20 -> 371700000 | V20: 300000000 | W20: Plan KPMG | X20: — | Y20: KPMG p. 78 — logistique FIFO et optimisation du stockage de l'abattoir
B21: PI-17 | C21: III | D21: OAC & Poussins | E21: Accroître et saturer les capacités de production | F21: 11 | G21: OAC | H21: Extension ferme OAC n°3 | I21: Notto | J21: À définir | K21: Ferme / bâtiment d'élevage | L21: Plan | M21: 2028-01 | N21: 2028-12 | O21: 2028 | P21: 2800000000 | Q21: 2800000000 | R21: =Q21-P21 -> 0 | S21: 140000000 | T21: =ROUND((Q21+S21)*0.18,0) -> 529200000 | U21: =Q21+S21+T21 -> 3469200000 | V21: 2800000000 | W21: Plan KPMG | X21: 30 | Y21: KPMG p. 17 — troisième des quatre extensions
B22: PI-18 | C22: III | D22: Œufs de table | E22: Accroître et saturer les capacités de production | F22: 11 | G22: PPAP | H22: Ferme poulettes 17 semaines n°3 | I22: TBD | J22: À définir | K22: Ferme / bâtiment d'élevage | L22: Plan | M22: 2028-01 | N22: 2029-04 | O22: 2028 | P22: 1000000000 | Q22: 1000000000 | R22: =Q22-P22 -> 0 | S22: 50000000 | T22: =ROUND((Q22+S22)*0.18,0) -> 189000000 | U22: =Q22+S22+T22 -> 1239000000 | V22: 1000000000 | W22: Plan KPMG | X22: 32 | Y22: KPMG p. 75 — troisième des trois fermes type Karaouni 2 | Z22: Porte la capacité MEP 17s à 1,9 m/an, cible 2030.
B23: PI-19 | C23: III | D23: OAC & Poussins | E23: Accroître et saturer les capacités de production | F23: 11 | G23: ODT | H23: Ferme ponte n°2 | I23: TBD | J23: À définir | K23: Ferme / bâtiment d'élevage | L23: Plan | M23: 2028-01 | N23: 2029-04 | O23: 2028 | P23: 1500000000 | Q23: 1500000000 | R23: =Q23-P23 -> 0 | S23: 75000000 | T23: =ROUND((Q23+S23)*0.18,0) -> 283500000 | U23: =Q23+S23+T23 -> 1858500000 | V23: 1500000000 | W23: Plan KPMG | X23: 35 | Y23: KPMG p. 75 — deuxième des trois fermes ponte
B24: PI-20 | C24: III | D24: Poulets de chair | E24: Accroître et saturer les capacités de production | F24: 11 | G24: Abattoir | H24: Ferme d'élevage poulet de chair n°2 | I24: TBD | J24: À définir | K24: Ferme / bâtiment d'élevage | L24: Plan | M24: 2028-01 | N24: 2029-04 | O24: 2028 | P24: 1000000000 | Q24: 1000000000 | R24: =Q24-P24 -> 0 | S24: 50000000 | T24: =ROUND((Q24+S24)*0.18,0) -> 189000000 | U24: =Q24+S24+T24 -> 1239000000 | V24: 1000000000 | W24: Plan KPMG | X24: 30 | Y24: KPMG p. 75 — deuxième des trois fermes chair
B25: PI-21 | C25: III | D25: Industriel | E25: Étudier les opportunités de diversification | F25: 15 | G25: Pâtes | H25: Usine de pâtes et couscous | I25: TBD | J25: À définir | K25: Usine et process industriel | L25: Plan | M25: 2028-01 | N25: 2029-06 | O25: 2028 | P25: 4021000000 | Q25: 4021000000 | R25: =Q25-P25 -> 0 | S25: 201050000 | T25: =ROUND((Q25+S25)*0.18,0) -> 759969000 | U25: =Q25+S25+T25 -> 4982019000 | V25: 4021000000 | W25: Plan KPMG | X25: — | Y25: KPMG p. 74 — janvier à décembre 2028, 25 kt de farine boulangère | Z25: Nouvelle activité. 36 740 M de CA attendus en 2030 — le plus fort gain du plan.
B26: PI-22 | C26: III | D26: Autres | E26: Maîtriser les coûts opérationnels | F26: 12 | G26: Général | H26: Panneaux solaires en autoconsommation | I26: Multi-sites | J26: À définir | K26: Usine et process industriel | L26: Plan | M26: 2028-01 | N26: 2028-12 | O26: 2028 | P26: 400000000 | Q26: 400000000 | R26: =Q26-P26 -> 0 | S26: 20000000 | T26: =ROUND((Q26+S26)*0.18,0) -> 75600000 | U26: =Q26+S26+T26 -> 495600000 | V26: 400000000 | W26: Plan KPMG | X26: — | Y26: KPMG p. 77 — pose en autoconsommation, 84 M de gains, 5 M d'Opex | Z26: Volet « énergie verte » du plan, à préciser site par site.
B27: PI-23 | C27: III | D27: Poulets de chair | E27: Accroître et saturer les capacités de production | F27: 11 | G27: Abattoir | H27: Refroidissement à l'air pour le poulet frais | I27: Ndiar | J27: À définir | K27: Usine et process industriel | L27: Plan | M27: 2028-01 | N27: 2028-12 | O27: 2028 | P27: 300000000 | Q27: 300000000 | R27: =Q27-P27 -> 0 | S27: 15000000 | T27: =ROUND((Q27+S27)*0.18,0) -> 56700000 | U27: =Q27+S27+T27 -> 371700000 | V27: 300000000 | W27: Plan KPMG | X27: — | Y27: KPMG p. 76 — installations de refroidissement à l'air, 220 M de gains
B28: PI-24 | C28: III | D28: OAC & Poussins | E28: Accroître et saturer les capacités de production | F28: 11 | G28: OAC | H28: Extension ferme OAC n°4 | I28: Notto | J28: À définir | K28: Ferme / bâtiment d'élevage | L28: Plan | M28: 2029-01 | N28: 2029-12 | O28: 2029 | P28: 2800000000 | Q28: 2800000000 | R28: =Q28-P28 -> 0 | S28: 140000000 | T28: =ROUND((Q28+S28)*0.18,0) -> 529200000 | U28: =Q28+S28+T28 -> 3469200000 | V28: 2800000000 | W28: Plan KPMG | X28: 30 | Y28: KPMG p. 17 — dernière des quatre extensions | Z28: Porte les repro chair à ~300 k effectifs, cible 2030.
B29: PI-25 | C29: III | D29: OAC & Poussins | E29: Accroître et saturer les capacités de production | F29: 11 | G29: ODT | H29: Ferme ponte n°3 | I29: TBD | J29: À définir | K29: Ferme / bâtiment d'élevage | L29: Plan | M29: 2029-01 | N29: 2030-04 | O29: 2029 | P29: 1500000000 | Q29: 1500000000 | R29: =Q29-P29 -> 0 | S29: 75000000 | T29: =ROUND((Q29+S29)*0.18,0) -> 283500000 | U29: =Q29+S29+T29 -> 1858500000 | V29: 1500000000 | W29: Plan KPMG | X29: 35 | Y29: KPMG p. 75 — dernière des trois fermes ponte | Z29: Porte les effectifs ponte à 1,6 m, cible 2030.
B30: PI-26 | C30: III | D30: Poulets de chair | E30: Accroître et saturer les capacités de production | F30: 11 | G30: Abattoir | H30: Ferme d'élevage poulet de chair n°3 | I30: TBD | J30: À définir | K30: Ferme / bâtiment d'élevage | L30: Plan | M30: 2029-01 | N30: 2030-04 | O30: 2029 | P30: 1000000000 | Q30: 1000000000 | R30: =Q30-P30 -> 0 | S30: 50000000 | T30: =ROUND((Q30+S30)*0.18,0) -> 189000000 | U30: =Q30+S30+T30 -> 1239000000 | V30: 1000000000 | W30: Plan KPMG | X30: 30 | Y30: KPMG p. 75 — dernière des trois fermes chair
B31: PI-01 | C31: III | D31: Œufs de table | E31: Accroître et saturer les capacités de production | F31: 11 | G31: ODT | H31: Réhabilitation Karaouni 1 / Facco 3 | I31: Karaouni 1 | J31: Pape Samba Mbengue | K31: Ferme / bâtiment d'élevage | L31: Hors périmètre | M31: 2026-01 | N31: 2027-01 | O31: 2026 | P31: 235489640 | Q31: 235489640 | R31: =Q31-P31 -> 0 | S31: 11774482 | T31: =ROUND((Q31+S31)*0.18,0) -> 44507542 | U31: =Q31+S31+T31 -> 291771664 | V31: 500000000 | W31: Estimation | X31: 23 | Y31: Officine Facco P005591-26-001377-A-1 du 12/03/2026 — restructuration poussinière Facco 3, 34 992 poulettes, batteries P80 4 étages, 165 000 € CFR Dakar | Z31: Remise à niveau de bâtiments d'élevage — sorti du périmètre, à reprendre ultérieurement. Une offre réelle existe déjà : 108 232 905 F, soit 46 % de l'enveloppe, montage et supervision exclus. L'enveloppe de 235 489 640 paraît courte.
B32: PI-27 | C32: III | D32: OAC & Poussins | E32: Accroître et saturer les capacités de production | F32: 11 | G32: OAC | H32: Remise à niveau des installations OAC | I32: Notto | J32: À définir | K32: Ferme / bâtiment d'élevage | L32: Hors périmètre | M32: 2026-01 | N32: 2029-12 | O32: 2026 | P32: 500000000 | Q32: 500000000 | R32: =Q32-P32 -> 0 | S32: 25000000 | T32: =ROUND((Q32+S32)*0.18,0) -> 94500000 | U32: =Q32+S32+T32 -> 619500000 | V32: 500000000 | W32: Plan KPMG | X32: — | Y32: KPMG p. 75 — 500 M pour la remise à niveau, inclus dans l'enveloppe OAC de 11 700 M | Z32: Remise à niveau de bâtiments d'élevage — sorti du périmètre.
B33: PI-28 | C33: III | D33: Œufs de table | E33: Accroître et saturer les capacités de production | F33: 11 | G33: ODT | H33: Remise à niveau poulettes et ponte — solde | I33: Multi-sites | J33: À définir | K33: Ferme / bâtiment d'élevage | L33: Hors périmètre | M33: 2026-01 | N33: 2029-12 | O33: 2026 | P33: 264510360 | Q33: 264510360 | R33: =Q33-P33 -> 0 | S33: 13225518 | T33: =ROUND((Q33+S33)*0.18,0) -> 49992458 | U33: =Q33+S33+T33 -> 327728336 | V33: 0 | W33: Plan KPMG | X33: — | Y33: Solde des 500 M KPMG après déduction de PI-01 (235 489 640) | Z33: Remise à niveau de bâtiments d'élevage — sorti du périmètre.
H34: TOTAL PORTEFEUILLE | P34: =SUM(P6:P33) -> 39829912544 | Q34: =SUM(Q6:Q33) -> 38705433765 | R34: =SUM(R6:R33) -> -1124478779 | S34: =SUM(S6:S33) -> 1811891592 | T34: =SUM(T6:T33) -> 7293118564 | U34: =SUM(U6:U33) -> 47810443921 | V34: =SUM(V6:V33) -> 37669000000

Sheet Tâches
B2: Tâches — découpage en lots des projets cadrés
B3: 583 tâches sur 19 projets. Dix projets portent un découpage propre ; neuf sont des répliques générées depuis un gabarit — les extensions OAC depuis PI-03, les fermes poulettes depuis PI-02, les fermes OAC ponte depuis PI-04, les fermes chair depuis PI-05. Les montants répliqués sont mis à l'échelle au prorata sur l'enveloppe cible et leur méthode est ramenée à Ratio, confiance faible : un gabarit n'est pas un devis. Début et Fin sont des semaines relatives au démarrage du projet.
B5: Code projet | C5: Code lot | D5: Nom du lot | E5: Responsable | F5: Code tâche | G5: Nom de la tâche | H5: Durée (sem.) | I5: Type de lien | J5: Tâche liée | K5: Début (sem.) | L5: Fin (sem.) | M5: HTVA | N5: Douanes | O5: TVA | P5: Total TTC | Q5: Source | R5: Méthode | S5: Confiance
B6: PI-01 | C6: L1 | D6: Diagnostic, études et phasage | E6: Chef de projet | F6: L1.1 | G6: État des lieux bâtiment par bâtiment et relevé des désordres | H6: 3 | K6: 1 | L6: 3 | M6: 4000000 | N6: 0 | O6: =ROUND((M6+N6)*0.18,0) -> 720000 | P6: =M6+N6+O6 -> 4720000 | Q6: Réhabilitation — le périmètre dépend de l'état constaté | R6: Avis d'expert | S6: Moyen
B7: PI-01 | C7: L1 | D7: Diagnostic, études et phasage | E7: Chef de projet | F7: L1.2 | G7: Études techniques et métrés (toitures, sols, ventilation) | H7: 3 | I7: FD | J7: L1.1 | K7: 4 | L7: 6 | M7: 5000000 | N7: 0 | O7: =ROUND((M7+N7)*0.18,0) -> 900000 | P7: =M7+N7+O7 -> 5900000 | Q7: Trois postes cités par la fiche projet | R7: Avis d'expert | S7: Moyen
B8: PI-01 | C8: L1 | D8: Diagnostic, études et phasage | E8: Chef de projet | F8: L1.3 | G8: Planning de phasage calé sur les vides sanitaires | H8: 2 | I8: FD | J8: L1.2 | K8: 7 | L8: 8 | M8: 0 | N8: 0 | O8: =ROUND((M8+N8)*0.18,0) -> 0 | P8: =M8+N8+O8 -> 0 | Q8: Sites en production — réhabilitation bâtiment par bâtiment | R8: Avis d'expert | S8: Faible
B9: PI-01 | C9: L1 | D9: Diagnostic, études et phasage | E9: Chef de projet | F9: L1.4 | G9: Consultation des entreprises et contractualisation | H9: 5 | I9: FD | J9: L1.2 | K9: 7 | L9: 11 | M9: 3000000 | N9: 0 | O9: =ROUND((M9+N9)*0.18,0) -> 540000 | P9: =M9+N9+O9 -> 3540000 | Q9: Aucune offre au dossier à ce jour | R9: Avis d'expert | S9: Moyen
B10: PI-01 | C10: L2 | D10: Réfection des toitures | E10: Conducteur de travaux | F10: L2.1 | G10: Approvisionnement des matériaux de couverture et isolation | H10: 6 | I10: FD | J10: L1.4 | K10: 12 | L10: 17 | M10: 40000000 | N10: 0 | O10: =ROUND((M10+N10)*0.18,0) -> 7200000 | P10: =M10+N10+O10 -> 47200000 | Q10: Risque identifié : retard d'approvisionnement, double sourcing local | R10: Ratio | S10: Faible
B11: PI-01 | C11: L2 | D11: Réfection des toitures | E11: Conducteur de travaux | F11: L2.2 | G11: Réfection des toitures — Karaouni 1 | H11: 6 | I11: FD | J11: L2.1 | K11: 18 | L11: 23 | M11: 16000000 | N11: 0 | O11: =ROUND((M11+N11)*0.18,0) -> 2880000 | P11: =M11+N11+O11 -> 18880000 | Q11: Répartition d'enveloppe — aucun devis reçu | R11: Ratio | S11: Faible
B12: PI-01 | C12: L2 | D12: Réfection des toitures | E12: Conducteur de travaux | F12: L2.3 | G12: Réfection des toitures — Facco 3 | H12: 5 | I12: FD | J12: L2.2 | K12: 24 | L12: 28 | M12: 12000000 | N12: 0 | O12: =ROUND((M12+N12)*0.18,0) -> 2160000 | P12: =M12+N12+O12 -> 14160000 | Q12: Répartition d'enveloppe — décalé pour ne pas arrêter les deux sites | R12: Ratio | S12: Faible
B13: PI-01 | C13: L3 | D13: Reprise des sols et maçonneries | E13: Conducteur de travaux | F13: L3.1 | G13: Démolition des sols dégradés et évacuation des gravats | H13: 3 | I13: FD | J13: L2.2 | K13: 24 | L13: 26 | M13: 10000000 | N13: 0 | O13: =ROUND((M13+N13)*0.18,0) -> 1800000 | P13: =M13+N13+O13 -> 11800000 | Q13: Répartition d'enveloppe | R13: Ratio | S13: Faible
B14: PI-01 | C14: L3 | D14: Reprise des sols et maçonneries | E14: Conducteur de travaux | F14: L3.2 | G14: Reprise des dallages et chapes | H14: 5 | I14: FD | J14: L3.1 | K14: 27 | L14: 31 | M14: 25000000 | N14: 0 | O14: =ROUND((M14+N14)*0.18,0) -> 4500000 | P14: =M14+N14+O14 -> 29500000 | Q14: Fiche projet — « reprise des sols » | R14: Ratio | S14: Faible
B15: PI-01 | C15: L3 | D15: Reprise des sols et maçonneries | E15: Conducteur de travaux | F15: L3.3 | G15: Reprise des maçonneries, seuils et ouvertures | H15: 4 | I15: FD | J15: L3.2 | K15: 32 | L15: 35 | M15: 10000000 | N15: 0 | O15: =ROUND((M15+N15)*0.18,0) -> 1800000 | P15: =M15+N15+O15 -> 11800000 | Q15: Répartition d'enveloppe | R15: Ratio | S15: Faible
B16: PI-01 | C16: L4 | D16: Remise à niveau de la ventilation | E16: Responsable technique élevage | F16: L4.1 | G16: Commande des ventilateurs, pads et régulation d'ambiance | H16: 10 | I16: FD | J16: L1.4 | K16: 12 | L16: 21 | M16: 55000000 | N16: 8094956 | O16: =ROUND((M16+N16)*0.18,0) -> 11357092 | P16: =M16+N16+O16 -> 74452048 | Q16: Équipement importé — poste le plus lourd après les toitures | R16: Ratio | S16: Faible
B17: PI-01 | C17: L4 | D17: Remise à niveau de la ventilation | E17: Responsable technique élevage | F17: L4.2 | G17: Transport, dédouanement et acheminement | H17: 4 | I17: FD | J17: L4.1 | K17: 22 | L17: 25 | M17: 0 | N17: 0 | O17: =ROUND((M17+N17)*0.18,0) -> 0 | P17: =M17+N17+O17 -> 0 | Q17: Droits de douane portés par la tâche de commande | R17: Avis d'expert | S17: Moyen
B18: PI-01 | C18: L4 | D18: Remise à niveau de la ventilation | E18: Responsable technique élevage | F18: L4.3 | G18: Dépose de l'ancienne ventilation | H18: 2 | I18: FD | J18: L3.3 | K18: 36 | L18: 37 | M18: 0 | N18: 0 | O18: =ROUND((M18+N18)*0.18,0) -> 0 | P18: =M18+N18+O18 -> 0 | Q18: À réaliser bâtiment vide — contrainte de phasage | R18: Avis d'expert | S18: Moyen
... B28: PI-01 | C28: L8 | D28: Remise en production et transfert | E28: Responsable production | F28: L8.2 | G28: Mise en place du lot et transfert à l'exploitation | H28: 2 | I28: FD | J28: L8.1 | K28: 52 | L28: 53 | M28: 2000000 | N28: 0 | O28: =ROUND((M28+N28)*0.18,0) -> 360000 | P28: =M28+N28+O28 -> 2360000 | Q28: Créneaux poulettes à réserver en amont | R28: Avis d'expert | S28: Moyen
B29: PI-02 | C29: L1 | D29: Études, terrain et autorisations | E29: Chef de projet | F29: L1.1 | G29: Choix et sécurisation foncière du site | H29: 6 | K29: 1 | L29: 6 | M29: 8000000 | N29: 0 | O29: =ROUND((M29+N29)*0.18,0) -> 1440000 | P29: =M29+N29+O29 -> 9440000 | Q29: SITE NON ARRÊTÉ — le projet est enregistré site « TBD » | R29: Avis d'expert | S29: Faible
B30: PI-02 | C30: L1 | D30: Études, terrain et autorisations | E30: Chef de projet | F30: L1.2 | G30: Études géotechniques et relevé topographique | H30: 4 | I30: FD | J30: L1.1 | K30: 7 | L30: 10 | M30: 5000000 | N30: 0 | O30: =ROUND((M30+N30)*0.18,0) -> 900000 | P30: =M30+N30+O30 -> 5900000 | Q30: Préalable au dimensionnement des fondations | R30: Avis d'expert | S30: Moyen
B31: PI-02 | C31: L1 | D31: Études, terrain et autorisations | E31: Chef de projet | F31: L1.3 | G31: Études d'exécution et implantation des 4 bâtiments (180 000 places) | H31: 6 | I31: FD | J31: L1.2 | K31: 11 | L31: 16 | M31: 12000000 | N31: 0 | O31: =ROUND((M31+N31)*0.18,0) -> 2160000 | P31: =M31+N31+O31 -> 14160000 | Q31: Dimensionnement arrêté : 180 000 places, 4 bâtiments de 45 000 | R31: Avis d'expert | S31: Moyen
B32: PI-02 | C32: L1 | D32: Études, terrain et autorisations | E32: Chef de projet | F32: L1.4 | G32: Autorisations, permis de construire et étude d'impact | H32: 8 | I32: FD | J32: L1.2 | K32: 11 | L32: 18 | M32: 6000000 | N32: 0 | O32: =ROUND((M32+N32)*0.18,0) -> 1080000 | P32: =M32+N32+O32 -> 7080000 | Q32: Élevage soumis à autorisation environnementale | R32: Avis d'expert | S32: Faible
B33: PI-02 | C33: L1 | D33: Études, terrain et autorisations | E33: Chef de projet | F33: L1.5 | G33: Consultation des fournisseurs et contractualisation | H33: 6 | I33: FD | J33: L1.3 | K33: 17 | L33: 22 | M33: 4000000 | N33: 0 | O33: =ROUND((M33+N33)*0.18,0) -> 720000 | P33: =M33+N33+O33 -> 4720000 | Q33: KPMG PP11 — « obtenir les devis et valider le budget ajusté » | R33: Avis d'expert | S33: Moyen
B34: PI-02 | C34: L2 | D34: VRD et aménagement du site | E34: Conducteur de travaux | F34: L2.1 | G34: Terrassement, plateforme et voiries internes | H34: 6 | I34: FD | J34: L1.5 | K34: 23 | L34: 28 | M34: 35000000 | N34: 0 | O34: =ROUND((M34+N34)*0.18,0) -> 6300000 | P34: =M34+N34+O34 -> 41300000 | Q34: Répartition d'enveloppe — aucun devis reçu | R34: Ratio | S34: Faible
B35: PI-02 | C35: L2 | D35: VRD et aménagement du site | E35: Conducteur de travaux | F35: L2.2 | G35: Clôture périmétrique, portail et sas d'entrée | H35: 4 | I35: FD | J35: L2.1 | K35: 29 | L35: 32 | M35: 10000000 | N35: 0 | O35: =ROUND((M35+N35)*0.18,0) -> 1800000 | P35: =M35+N35+O35 -> 11800000 | Q35: Exigence de biosécurité — périmètre clos obligatoire | R35: Ratio | S35: Faible
B36: PI-02 | C36: L2 | D36: VRD et aménagement du site | E36: Conducteur de travaux | F36: L2.3 | G36: Forage, adduction d'eau et réservoir | H36: 6 | I36: DD | J36: L2.1 | K36: 23 | L36: 28 | M36: 15000000 | N36: 0 | O36: =ROUND((M36+N36)*0.18,0) -> 2700000 | P36: =M36+N36+O36 -> 17700000 | Q36: KPMG PP11 — « approvisionnement continu en aliment et en eau » | R36: Ratio | S36: Faible
B37: PI-02 | C37: L3 | D37: Génie civil | E37: Conducteur de travaux | F37: L3.1 | G37: Fondations, semelles et longrines | H37: 5 | I37: FD | J37: L2.1 | K37: 29 | L37: 33 | M37: 70000000 | N37: 0 | O37: =ROUND((M37+N37)*0.18,0) -> 12600000 | P37: =M37+N37+O37 -> 82600000 | Q37: Répartition d'enveloppe — à confirmer après étude de sol | R37: Ratio | S37: Faible
B38: PI-02 | C38: L3 | D38: Génie civil | E38: Conducteur de travaux | F38: L3.2 | G38: Dallage des 4 bâtiments d'élevage | H38: 4 | I38: FD | J38: L3.1 | K38: 34 | L38: 37 | M38: 65000000 | N38: 0 | O38: =ROUND((M38+N38)*0.18,0) -> 11700000 | P38: =M38+N38+O38 -> 76700000 | Q38: Répartition d'enveloppe | R38: Ratio | S38: Faible
B39: PI-02 | C39: L3 | D39: Génie civil | E39: Conducteur de travaux | F39: L3.3 | G39: Locaux techniques, magasin d'aliment et logement de garde | H39: 6 | I39: FD | J39: L3.2 | K39: 38 | L39: 43 | M39: 45000000 | N39: 0 | O39: =ROUND((M39+N39)*0.18,0) -> 8100000 | P39: =M39+N39+O39 -> 53100000 | Q39: Répartition d'enveloppe | R39: Ratio | S39: Faible
B40: PI-02 | C40: L4 | D40: Structure métallique, bardage et couverture | E40: Conducteur de travaux | F40: L4.1 | G40: Fabrication de la charpente métallique | H40: 7 | I40: FD | J40: L1.5 | K40: 23 | L40: 29 | M40: 190000000 | N40: 0 | O40: =ROUND((M40+N40)*0.18,0) -> 34200000 | P40: =M40+N40+O40 -> 224200000 | Q40: Répartition d'enveloppe — poste le plus lourd du projet | R40: Ratio | S40: Faible
B41: PI-02 | C41: L4 | D41: Structure métallique, bardage et couverture | E41: Conducteur de travaux | F41: L4.2 | G41: Montage de la charpente sur site | H41: 6 | I41: FD | J41: L3.2 | K41: 38 | L41: 43 | M41: 60000000 | N41: 0 | O41: =ROUND((M41+N41)*0.18,0) -> 10800000 | P41: =M41+N41+O41 -> 70800000 | Q41: Répartition d'enveloppe | R41: Ratio | S41: Faible
... B60: PI-02 | C60: L10 | D60: Mise en service et transfert à l'exploitation | E60: Responsable production | F60: L10.4 | G60: Mise en place du premier lot et transfert à l'exploitation | H60: 2 | I60: FD | J60: L10.2 | K60: 64 | L60: 65 | M60: 4000000 | N60: 0 | O60: =ROUND((M60+N60)*0.18,0) -> 720000 | P60: =M60+N60+O60 -> 4720000 | Q60: 180 000 poussins à réserver au couvoir 12 semaines à l'avance | R60: Avis d'expert | S60: Moyen
B61: PI-03 | C61: L1 | D61: Études et autorisations | E61: Chef de projet | F61: L1.2 | G61: Étude géotechnique et implantation | H61: 2 | I61: DD | J61: L1.1 | K61: 1 | L61: 2 | M61: 29290000 | N61: 0 | O61: =ROUND((M61+N61)*0.18,0) -> 5272200 | P61: =M61+N61+O61 -> 34562200 | R61: Faible | S61: Faible
B62: PI-03 | C62: L1 | D62: Études et autorisations | E62: Chef de projet | F62: L1.3 | G62: Autorisations et permis de construire | H62: 6 | I62: FD | J62: L1.1 | K62: 1 | L62: 6 | M62: 29290000 | N62: 0 | O62: =ROUND((M62+N62)*0.18,0) -> 5272200 | P62: =M62+N62+O62 -> 34562200 | R62: Faible | S62: Faible
B63: PI-03 | C63: L1 | D63: Études et autorisations | E63: Chef de projet | F63: L1.4 | G63: Consultation et attribution du marché génie civil | H63: 6 | I63: FD | J63: L1.1 | K63: 1 | L63: 6 | M63: 29290000 | N63: 0 | O63: =ROUND((M63+N63)*0.18,0) -> 5272200 | P63: =M63+N63+O63 -> 34562200 | R63: Faible | S63: Faible
B64: PI-03 | C64: L2 | D64: VRD et renforcements | E64: Conducteur de travaux | F64: L2.1 | G64: Terrassement et plateformes | H64: 4 | I64: FD | J64: L1.3 | K64: 7 | L64: 10 | M64: 73225000 | N64: 0 | O64: =ROUND((M64+N64)*0.18,0) -> 13180500 | P64: =M64+N64+O64 -> 86405500 | R64: Faible | S64: Faible
B65: PI-03 | C65: L2 | D65: VRD et renforcements | E65: Conducteur de travaux | F65: L2.2 | G65: Renforcement du forage et adduction d'eau | H65: 4 | I65: FD | J65: L2.1 | K65: 11 | L65: 14 | M65: 73225000 | N65: 0 | O65: =ROUND((M65+N65)*0.18,0) -> 13180500 | P65: =M65+N65+O65 -> 86405500 | R65: Faible | S65: Faible
B66: PI-03 | C66: L2 | D66: VRD et renforcements | E66: Conducteur de travaux | F66: L2.3 | G66: Renforcement électrique et groupe de secours | H66: 5 | I66: DD | J66: L2.2 | K66: 11 | L66: 15 | M66: 73225000 | N66: 0 | O66: =ROUND((M66+N66)*0.18,0) -> 13180500 | P66: =M66+N66+O66 -> 86405500 | R66: Faible | S66: Faible
B67: PI-03 | C67: L2 | D67: VRD et renforcements | E67: Conducteur de travaux | F67: L2.4 | G67: Voirie interne et clôture périmétrique | H67: 4 | I67: FD | J67: L2.1 | K67: 11 | L67: 14 | M67: 73225000 | N67: 0 | O67: =ROUND((M67+N67)*0.18,0) -> 13180500 | P67: =M67+N67+O67 -> 86405500 | R67: Faible | S67: Faible
B68: PI-03 | C68: L3 | D68: Génie civil des 6 bâtiments | E68: Conducteur de travaux | F68: L3.1 | G68: Fondations et dallages — poussinières | H68: 5 | I68: FD | J68: L2.1 | K68: 11 | L68: 15 | M68: 278255000 | N68: 0 | O68: =ROUND((M68+N68)*0.18,0) -> 50085900 | P68: =M68+N68+O68 -> 328340900 | R68: Faible | S68: Faible
B69: PI-03 | C69: L3 | D69: Génie civil des 6 bâtiments | E69: Conducteur de travaux | F69: L3.2 | G69: Structures, couvertures et bardages — poussinières | H69: 7 | I69: FD | J69: L3.1 | K69: 16 | L69: 22 | M69: 278255000 | N69: 0 | O69: =ROUND((M69+N69)*0.18,0) -> 50085900 | P69: =M69+N69+O69 -> 328340900 | R69: Faible | S69: Faible
...

Sheet Tranches
B2: Répartition pluriannuelle du CAPEX
B3: Chaque projet porte son coût reconstruit sur l'exercice retenu par le plan. La répartition est modifiable ligne par ligne : la colonne Contrôle vérifie que la somme des exercices égale le coût du projet. Les projets s'étalant sur deux exercices — moulin, usine de pâtes, fermes — pourront y être répartis sans que le total ne bouge.
B5: Code | C5: Nom du projet | D5: Bucket | E5: Statut | F5: Coût reconstruit | G5: 2026 | H5: 2027 | I5: 2028 | J5: 2029 | K5: 2030 | L5: Contrôle
B6: PI-02 | C6: Nouveau bâtiment PAP17 | D6: Œufs de table | E6: Cadrage | F6: 1000000000 | G6: 1000000000 | H6: 0 | I6: 0 | J6: 0 | K6: 0 | L6: =IF(SUM(G6:K6)=F6,"OK","ÉCART") -> OK
B7: PI-03 | C7: Extension ferme OAC | D7: OAC & Poussins | E7: Cadrage | F7: 2899710000 | G7: 2899710000 | H7: 0 | I7: 0 | J7: 0 | K7: 0 | L7: =IF(SUM(G7:K7)=F7,"OK","ÉCART") -> OK
B8: PI-06 | C8: Automatisation Couvoir | D8: OAC & Poussins | E8: Engagé | F8: 207934725 | G8: 207934725 | H8: 0 | I8: 0 | J8: 0 | K8: 0 | L8: =IF(SUM(G8:K8)=F8,"OK","ÉCART") -> OK
B9: PI-07 | C9: Remise à niveau abattoir | D9: Poulets de chair | E9: Engagé | F9: 1153434670 | G9: 1153434670 | H9: 0 | I9: 0 | J9: 0 | K9: 0 | L9: =IF(SUM(G9:K9)=F9,"OK","ÉCART") -> OK
B10: PI-08 | C10: Extension UAB | D10: Industriel | E10: Engagé | F10: 1832414627 | G10: 1832414627 | H10: 0 | I10: 0 | J10: 0 | K10: 0 | L10: =IF(SUM(G10:K10)=F10,"OK","ÉCART") -> OK
B11: PI-10 | C11: Digitalisation 2026 | D11: Autres | E11: Cadrage | F11: 126000000 | G11: 126000000 | H11: 0 | I11: 0 | J11: 0 | K11: 0 | L11: =IF(SUM(G11:K11)=F11,"OK","ÉCART") -> OK
B12: PI-11 | C12: Automatisation des pondoirs (12 bâtiments) | D12: Œufs de table | E12: Plan | F12: 516000000 | G12: 516000000 | H12: 0 | I12: 0 | J12: 0 | K12: 0 | L12: =IF(SUM(G12:K12)=F12,"OK","ÉCART") -> OK
B13: PI-12 | C13: Ligne de production de nuggets | D13: Poulets de chair | E13: Cadrage | F13: 120939743 | G13: 120939743 | H13: 0 | I13: 0 | J13: 0 | K13: 0 | L13: =IF(SUM(G13:K13)=F13,"OK","ÉCART") -> OK
B14: PI-04 | C14: Ferme de production OAC ponte | D14: OAC & Poussins | E14: Plan | F14: 1500000000 | G14: 0 | H14: 1500000000 | I14: 0 | J14: 0 | K14: 0 | L14: =IF(SUM(G14:K14)=F14,"OK","ÉCART") -> OK
B15: PI-05 | C15: Ferme élevage poulet de chair | D15: Poulets de chair | E15: Plan | F15: 1246000000 | G15: 0 | H15: 1246000000 | I15: 0 | J15: 0 | K15: 0 | L15: =IF(SUM(G15:K15)=F15,"OK","ÉCART") -> OK
B16: PI-09 | C16: Extension Flotte logistique | D16: Autres | E16: Plan | F16: 513000000 | G16: 0 | H16: 513000000 | I16: 0 | J16: 0 | K16: 0 | L16: =IF(SUM(G16:K16)=F16,"OK","ÉCART") -> OK
B17: PI-13 | C17: Extension ferme OAC n°2 | D17: OAC & Poussins | E17: Plan | F17: 2800000000 | G17: 0 | H17: 2800000000 | I17: 0 | J17: 0 | K17: 0 | L17: =IF(SUM(G17:K17)=F17,"OK","ÉCART") -> OK
... B33: PI-28 | C33: Remise à niveau poulettes et ponte — solde | D33: Œufs de table | E33: Hors périmètre | F33: 264510360 | G33: 264510360 | H33: 0 | I33: 0 | J33: 0 | K33: 0 | L33: =IF(SUM(G33:K33)=F33,"OK","ÉCART") -> OK
C34: TOTAL | F34: =SUM(F6:F33) -> 38705433765 | G34: =SUM(G6:G33) -> 8856433765 | H34: =SUM(H6:H33) -> 13528000000 | I34: =SUM(I6:I33) -> 11021000000 | J34: =SUM(J6:J33) -> 5300000000 | K34: =SUM(K6:K33) -> 0

Sheet Contrôle
B2: Contrôles de bouclage
B3: Cinq niveaux : enveloppes contre coûts reconstruits, exercices, objectifs du plan (page 10), cohérence portefeuille / tâches, et qualité de la donnée. Les écarts au plan ne sont pas des erreurs : ils mesurent la distance entre le chiffrage préliminaire de KPMG et les montants réellement contractés ou devisés.
B5: Contrôle | C5: Valeur | D5: Référence | E5: Écart | F5: Commentaire
B6: ENVELOPPES ET COÛTS RECONSTRUITS
B7: Total des enveloppes approuvées | C7: 39829912544
B8: Total des coûts reconstruits | C8: 38705433765 | D8: 39829912544 | E8: =C8-D8 -> -1124478779 | F8: L'écart net masque des mouvements de sens opposé, détaillés projet par projet au portefeuille.
B9: Enveloppe du plan KPMG | C9: 37669000000 | D9: 37670000000 | E9: =C9-D9 -> -1000000 | F9: 37 670 M annoncés page 10.
B11: PAR EXERCICE — COÛTS RECONSTRUITS
B12: CAPEX 2026 | C12: 8856433765 | D12: 8116000000 | E12: =C12-D12 -> 740433765 | F12: 11 projet(s)
B13: CAPEX 2027 | C13: 13528000000 | D13: 13232000000 | E13: =C13-D13 -> 296000000 | F13: 7 projet(s)
B14: CAPEX 2028 | C14: 11021000000 | D14: 11021000000 | E14: =C14-D14 -> 0 | F14: 7 projet(s)
B15: CAPEX 2029 | C15: 5300000000 | D15: 5300000000 | E15: =C15-D15 -> 0 | F15: 3 projet(s)
B16: CAPEX 2030 | C16: 0 | D16: 0 | E16: =C16-D16 -> 0 | F16: 0 projet(s)
B17: Total 2026-2030 | C17: 38705433765 | D17: 37669000000 | E17: =C17-D17 -> 1036433765
B19: PAR OBJECTIF DU PLAN — PAGE 10
B20: Pilier III · Accroître et saturer les capacités de production | C20: 31347124627 | D20: 31470000000 | E20: =C20-D20 -> -122875373 | F20: PI-08 rentre sous l'enveloppe grâce au contrat Bühler, GH-26 exclu du coût reconstruit.
B21: Pilier III · Maîtriser les coûts opérationnels | C21: 400000000 | D21: 400000000 | E21: =C21-D21 -> 0
B22: Pilier III · Automatiser les processus industriels | C22: 1877369395 | D22: 836000000 | E22: =C22-D22 -> 1041369395 | F22: PI-07 à 1 153 M sur 12 offres contre 160 M au plan ; PI-06 intègre 25 M de travaux locaux.
B23: Pilier III · Mettre à niveau la flotte logistique | C23: 813000000 | D23: 763000000 | E23: =C23-D23 -> 50000000 | F23: PI-09 intègre télématique, immatriculation et atelier, absents du chiffrage KPMG.
B24: Pilier III · Étudier les opportunités de diversification | C24: 4141939743 | D24: 4086000000 | E24: =C24-D24 -> 55939743
B25: Pilier II · Refonte de la politique commerciale | C25: 126000000 | D25: 115000000 | E25: =C25-D25 -> 11000000 | F25: Pilier II — rattachement au portefeuille Pilier III à trancher.
B27: COHÉRENCE PORTEFEUILLE / TÂCHES
B28: PI-01 — Réhabilitation Karaouni 1 / Facco 3 | C28: =SUMIF(Tâches!$B$6:$B$610,"PI-01",Tâches!$M$6:$M$610) -> 235489640 | D28: 235489640 | E28: =C28-D28 -> 0 | F28: 23 tâches · fin S53
B29: PI-02 — Nouveau bâtiment PAP17 | C29: =SUMIF(Tâches!$B$6:$B$610,"PI-02",Tâches!$M$6:$M$610) -> 1000000000 | D29: 1000000000 | E29: =C29-D29 -> 0 | F29: 32 tâches · fin S66
B30: PI-03 — Extension ferme OAC | C30: =SUMIF(Tâches!$B$6:$B$610,"PI-03",Tâches!$M$6:$M$610) -> 2899710000 | D30: 2899710000 | E30: =C30-D30 -> 0 | F30: 30 tâches · fin S77
B31: PI-04 — Ferme de production OAC ponte | C31: =SUMIF(Tâches!$B$6:$B$610,"PI-04",Tâches!$M$6:$M$610) -> 1500000000 | D31: 1500000000 | E31: =C31-D31 -> 0 | F31: 35 tâches · fin S85
B32: PI-05 — Ferme élevage poulet de chair | C32: =SUMIF(Tâches!$B$6:$B$610,"PI-05",Tâches!$M$6:$M$610) -> 1246000000 | D32: 1246000000 | E32: =C32-D32 -> 0 | F32: 30 tâches · fin S65
B33: PI-06 — Automatisation Couvoir | C33: =SUMIF(Tâches!$B$6:$B$610,"PI-06",Tâches!$M$6:$M$610) -> 207934725 | D33: 207934725 | E33: =C33-D33 -> 0 | F33: 31 tâches · fin S58
B34: PI-07 — Remise à niveau abattoir | C34: =SUMIF(Tâches!$B$6:$B$610,"PI-07",Tâches!$M$6:$M$610) -> 1153434670 | D34: 1153434670 | E34: =C34-D34 -> 0 | F34: 56 tâches · fin S53
B35: PI-08 — Extension UAB | C35: =SUMIF(Tâches!$B$6:$B$610,"PI-08",Tâches!$M$6:$M$610) -> 1832414627 | D35: 1832414627 | E35: =C35-D35 -> 0 | F35: 29 tâches · fin S77
B36: PI-09 — Extension Flotte logistique | C36: =SUMIF(Tâches!$B$6:$B$610,"PI-09",Tâches!$M$6:$M$610) -> 513000000 | D36: 513000000 | E36: =C36-D36 -> 0 | F36: 22 tâches · fin S74
B37: PI-10 — Digitalisation 2026 | C37: =SUMIF(Tâches!$B$6:$B$610,"PI-10",Tâches!$M$6:$M$610) -> 126000000 | D37: 126000000 | E37: =C37-D37 -> 0 | F37: 11 tâches · fin S37
B38: PI-12 — Ligne de production de nuggets | C38: =SUMIF(Tâches!$B$6:$B$610,"PI-12",Tâches!$M$6:$M$610) -> 120939743 | D38: 120939743 | E38: =C38-D38 -> 0 | F38: 22 tâches · fin S47
B39: PI-13 — Extension ferme OAC n°2 | C39: =SUMIF(Tâches!$B$6:$B$610,"PI-13",Tâches!$M$6:$M$610) -> 2800000000 | D39: 2800000000 | E39: =C39-D39 -> 0 | F39: 30 tâches · fin S77
B40: PI-14 — Ferme poulettes 17 semaines n°2 | C40: =SUMIF(Tâches!$B$6:$B$610,"PI-14",Tâches!$M$6:$M$610) -> 1000000000 | D40: 1000000000 | E40: =C40-D40 -> 0 | F40: 32 tâches · fin S66
B41: PI-17 — Extension ferme OAC n°3 | C41: =SUMIF(Tâches!$B$6:$B$610,"PI-17",Tâches!$M$6:$M$610) -> 2800000000 | D41: 2800000000 | E41: =C41-D41 -> 0 | F41: 30 tâches · fin S77
B42: PI-18 — Ferme poulettes 17 semaines n°3 | C42: =SUMIF(Tâches!$B$6:$B$610,"PI-18",Tâches!$M$6:$M$610) -> 1000000000 | D42: 1000000000 | E42: =C42-D42 -> 0 | F42: 32 tâches · fin S66
B43: PI-19 — Ferme ponte n°2 | C43: =SUMIF(Tâches!$B$6:$B$610,"PI-19",Tâches!$M$6:$M$610) -> 1500000000 | D43: 1500000000 | E43: =C43-D43 -> 0 | F43: 35 tâches · fin S85
B44: PI-20 — Ferme d'élevage poulet de chair n°2 | C44: =SUMIF(Tâches!$B$6:$B$610,"PI-20",Tâches!$M$6:$M$610) -> 1000000000 | D44: 1000000000 | E44: =C44-D44 -> 0 | F44: 30 tâches · fin S65
B45: PI-24 — Extension ferme OAC n°4 | C45: =SUMIF(Tâches!$B$6:$B$610,"PI-24",Tâches!$M$6:$M$610) -> 2800000000 | D45: 2800000000 | E45: =C45-D45 -> 0 | F45: 30 tâches · fin S77
...
